Workbook

Sheet Readme
A1: Fabric AI Readiness Assessment
A3: Rule pack version | B3: 2026.09.1
A4: Spec version | B4: 1.0.0
A5: Rules | B5: 138
A6: Updated | B6: 2026-09-10
A7: Purpose | B7: Config-driven rule pack measuring enablement, usage, response validity/relevance and performance posture for Power BI Copilot and Microsoft Fabric data agents. Designed so that AI query generation is narrowly scoped and grounded rather than broad-scanning an unconstrained schema.
A9: HOW TO USE
A10: 1 | B10: Work through one area tab at a time. Each row is one rule.
A11: 2 | B11: Set the yellow Result cell on every row: pass, partial, fail, na, or unknown.
A12: 3 | B12: Record where the evidence lives, who owns the fix, and the target date in the other yellow cells.
A13: 4 | B13: The Scoring tab recalculates live. Read the overall score and maturity level there.
A14: 5 | B14: Any blocker rule left at fail or unknown gates the maturity level at 0 regardless of score.
A16: EDIT ONLY THE YELLOW CELLS | B16: Every other cell restates the rule and should not be changed here. To change a rule, edit AssessmentRules.json and regenerate this workbook.
A17: THIS IS A VIEW, NOT THE SOURCE | B17: AssessmentRules.json is the source of truth. Add your own rules to rules/custom/*.json and rebuild.
A19: RESULT STATES
A20: pass | B20: Requirement met and evidenced. (credit 1.0)
A21: partial | B21: Partially met, e.g. applied to some models/agents but not all in scope. (credit 0.5)
A22: fail | B22: Requirement not met. (credit 0.0)
A23: na | B23: Out of scope for this estate; removed from both numerator and denominator. (excluded from scoring)
A24: unknown | B24: Not yet assessed. Scored as fail but reported separately as assessment debt. (credit 0.0)
A26: SEVERITY WEIGHTS
A27: blocker | B27: weight 13 - GATES the maturity level. AI features cannot function or cannot be trusted at all until fixed. A failed blocker caps overall maturity at Not Ready.
A28: critical | B28: weight 8. Materially wrong answers, security exposure, or severe cost/latency. Fix before broad rollout.
A29: high | B29: weight 5. Frequent ambiguity, degraded relevance, or avoidable capacity burn.
A30: medium | B30: weight 3. Noticeable quality or efficiency loss; fix during hardening.
A31: low | B31: weight 1. Polish and consistency; improves long-run maintainability.
A33: BASIS COLUMN
A34: documented | B34: Stated in a cited source. Treat the threshold as authoritative but re-verify against current docs.
A35: inferred | B35: Engineering judgement built on cited platform behaviour. Calibrate to your own risk appetite.
A36: community | B36: Unofficial. Verify before relying on it.

Sheet Scoring
A1: Readiness score
A3: Area | B3: Score % | C3: Weight | D3: Pass | E3: Partial | F3: Fail | G3: N/A | H3: Unknown | I3: Earned | J3: Possible
A4: Tenant & admin enablement | B4: =IFERROR(ROUND(100*I4/J4,1),"n/a") -> 0 | C4: 10 | D4: =COUNTIF('Tenant & admin enablement'!$N$3:$N$11,"pass") -> 0 | E4: =COUNTIF('Tenant & admin enablement'!$N$3:$N$11,"partial") -> 0 | F4: =COUNTIF('Tenant & admin enablement'!$N$3:$N$11,"fail") -> 0 | G4: =COUNTIF('Tenant & admin enablement'!$N$3:$N$11,"na") -> 0 | H4: =COUNTIF('Tenant & admin enablement'!$N$3:$N$11,"unknown") -> 9 | I4: =SUMIF('Tenant & admin enablement'!$N$3:$N$11,"pass",'Tenant & admin enablement'!$T$3:$T$11)+0.5*SUMIF('Tenant & admin enablement'!$N$3:$N$11,"partial",'Tenant & admin enablement'!$T$3:$T$11) -> 0 | J4: =SUM('Tenant & admin enablement'!$T$3:$T$11)-SUMIF('Tenant & admin enablement'!$N$3:$N$11,"na",'Tenant & admin enablement'!$T$3:$T$11) -> 63
A5: Capacity, SKU, region & cost | B5: =IFERROR(ROUND(100*I5/J5,1),"n/a") -> 0 | C5: 10 | D5: =COUNTIF('Capacity, SKU, region & cost'!$N$3:$N$8,"pass") -> 0 | E5: =COUNTIF('Capacity, SKU, region & cost'!$N$3:$N$8,"partial") -> 0 | F5: =COUNTIF('Capacity, SKU, region & cost'!$N$3:$N$8,"fail") -> 0 | G5: =COUNTIF('Capacity, SKU, region & cost'!$N$3:$N$8,"na") -> 0 | H5: =COUNTIF('Capacity, SKU, region & cost'!$N$3:$N$8,"unknown") -> 6 | I5: =SUMIF('Capacity, SKU, region & cost'!$N$3:$N$8,"pass",'Capacity, SKU, region & cost'!$T$3:$T$8)+0.5*SUMIF('Capacity, SKU, region & cost'!$N$3:$N$8,"partial",'Capacity, SKU, region & cost'!$T$3:$T$8) -> 0 | J5: =SUM('Capacity, SKU, region & cost'!$T$3:$T$8)-SUMIF('Capacity, SKU, region & cost'!$N$3:$N$8,"na",'Capacity, SKU, region & cost'!$T$3:$T$8) -> 50
A6: Workspace & item governance | B6: =IFERROR(ROUND(100*I6/J6,1),"n/a") -> 0 | C6: 6 | D6: =COUNTIF('Workspace & item governance'!$N$3:$N$9,"pass") -> 0 | E6: =COUNTIF('Workspace & item governance'!$N$3:$N$9,"partial") -> 0 | F6: =COUNTIF('Workspace & item governance'!$N$3:$N$9,"fail") -> 0 | G6: =COUNTIF('Workspace & item governance'!$N$3:$N$9,"na") -> 0 | H6: =COUNTIF('Workspace & item governance'!$N$3:$N$9,"unknown") -> 7 | I6: =SUMIF('Workspace & item governance'!$N$3:$N$9,"pass",'Workspace & item governance'!$T$3:$T$9)+0.5*SUMIF('Workspace & item governance'!$N$3:$N$9,"partial",'Workspace & item governance'!$T$3:$T$9) -> 0 | J6: =SUM('Workspace & item governance'!$T$3:$T$9)-SUMIF('Workspace & item governance'!$N$3:$N$9,"na",'Workspace & item governance'!$T$3:$T$9) -> 35
A7: AI data schema & scope reduction | B7: =IFERROR(ROUND(100*I7/J7,1),"n/a") -> 0 | C7: 14 | D7: =COUNTIF('AI data schema & scope reductio'!$N$3:$N$23,"pass") -> 0 | E7: =COUNTIF('AI data schema & scope reductio'!$N$3:$N$23,"partial") -> 0 | F7: =COUNTIF('AI data schema & scope reductio'!$N$3:$N$23,"fail") -> 0 | G7: =COUNTIF('AI data schema & scope reductio'!$N$3:$N$23,"na") -> 0 | H7: =COUNTIF('AI data schema & scope reductio'!$N$3:$N$23,"unknown") -> 21 | I7: =SUMIF('AI data schema & scope reductio'!$N$3:$N$23,"pass",'AI data schema & scope reductio'!$T$3:$T$23)+0.5*SUMIF('AI data schema & scope reductio'!$N$3:$N$23,"partial",'AI data schema & scope reductio'!$T$3:$T$23) -> 0 | J7: =SUM('AI data schema & scope reductio'!$T$3:$T$23)-SUMIF('AI data schema & scope reductio'!$N$3:$N$23,"na",'AI data schema & scope reductio'!$T$3:$T$23) -> 127
A8: Semantic model structure | B8: =IFERROR(ROUND(100*I8/J8,1),"n/a") -> 0 | C8: 12 | D8: =COUNTIF('Semantic model structure'!$N$3:$N$12,"pass") -> 0 | E8: =COUNTIF('Semantic model structure'!$N$3:$N$12,"partial") -> 0 | F8: =COUNTIF('Semantic model structure'!$N$3:$N$12,"fail") -> 0 | G8: =COUNTIF('Semantic model structure'!$N$3:$N$12,"na") -> 0 | H8: =COUNTIF('Semantic model structure'!$N$3:$N$12,"unknown") -> 10 | I8: =SUMIF('Semantic model structure'!$N$3:$N$12,"pass",'Semantic model structure'!$T$3:$T$12)+0.5*SUMIF('Semantic model structure'!$N$3:$N$12,"partial",'Semantic model structure'!$T$3:$T$12) -> 0 | J8: =SUM('Semantic model structure'!$T$3:$T$12)-SUMIF('Semantic model structure'!$N$3:$N$12,"na",'Semantic model structure'!$T$3:$T$12) -> 55
A9: Names, descriptions & linguistics | B9: =IFERROR(ROUND(100*I9/J9,1),"n/a") -> 0 | C9: 11 | D9: =COUNTIF('Names, descriptions & linguisti'!$N$3:$N$12,"pass") -> 0 | E9: =COUNTIF('Names, descriptions & linguisti'!$N$3:$N$12,"partial") -> 0 | F9: =COUNTIF('Names, descriptions & linguisti'!$N$3:$N$12,"fail") -> 0 | G9: =COUNTIF('Names, descriptions & linguisti'!$N$3:$N$12,"na") -> 0 | H9: =COUNTIF('Names, descriptions & linguisti'!$N$3:$N$12,"unknown") -> 10 | I9: =SUMIF('Names, descriptions & linguisti'!$N$3:$N$12,"pass",'Names, descriptions & linguisti'!$T$3:$T$12)+0.5*SUMIF('Names, descriptions & linguisti'!$N$3:$N$12,"partial",'Names, descriptions & linguisti'!$T$3:$T$12) -> 0 | J9: =SUM('Names, descriptions & linguisti'!$T$3:$T$12)-SUMIF('Names, descriptions & linguisti'!$N$3:$N$12,"na",'Names, descriptions & linguisti'!$T$3:$T$12) -> 56
A10: Measures & DAX | B10: =IFERROR(ROUND(100*I10/J10,1),"n/a") -> 0 | C10: 9 | D10: =COUNTIF('Measures & DAX'!$N$3:$N$14,"pass") -> 0 | E10: =COUNTIF('Measures & DAX'!$N$3:$N$14,"partial") -> 0 | F10: =COUNTIF('Measures & DAX'!$N$3:$N$14,"fail") -> 0 | G10: =COUNTIF('Measures & DAX'!$N$3:$N$14,"na") -> 0 | H10: =COUNTIF('Measures & DAX'!$N$3:$N$14,"unknown") -> 12 | I10: =SUMIF('Measures & DAX'!$N$3:$N$14,"pass",'Measures & DAX'!$T$3:$T$14)+0.5*SUMIF('Measures & DAX'!$N$3:$N$14,"partial",'Measures & DAX'!$T$3:$T$14) -> 0 | J10: =SUM('Measures & DAX'!$T$3:$T$14)-SUMIF('Measures & DAX'!$N$3:$N$14,"na",'Measures & DAX'!$T$3:$T$14) -> 59
A11: Data types & data quality | B11: =IFERROR(ROUND(100*I11/J11,1),"n/a") -> 0 | C11: 5 | D11: =COUNTIF('Data types & data quality'!$N$3:$N$7,"pass") -> 0 | E11: =COUNTIF('Data types & data quality'!$N$3:$N$7,"partial") -> 0 | F11: =COUNTIF('Data types & data quality'!$N$3:$N$7,"fail") -> 0 | G11: =COUNTIF('Data types & data quality'!$N$3:$N$7,"na") -> 0 | H11: =COUNTIF('Data types & data quality'!$N$3:$N$7,"unknown") -> 5 | I11: =SUMIF('Data types & data quality'!$N$3:$N$7,"pass",'Data types & data quality'!$T$3:$T$7)+0.5*SUMIF('Data types & data quality'!$N$3:$N$7,"partial",'Data types & data quality'!$T$3:$T$7) -> 0 | J11: =SUM('Data types & data quality'!$T$3:$T$7)-SUMIF('Data types & data quality'!$N$3:$N$7,"na",'Data types & data quality'!$T$3:$T$7) -> 22
A12: Security, RLS & compliance | B12: =IFERROR(ROUND(100*I12/J12,1),"n/a") -> 0 | C12: 8 | D12: =COUNTIF('Security, RLS & compliance'!$N$3:$N$10,"pass") -> 0 | E12: =COUNTIF('Security, RLS & compliance'!$N$3:$N$10,"partial") -> 0 | F12: =COUNTIF('Security, RLS & compliance'!$N$3:$N$10,"fail") -> 0 | G12: =COUNTIF('Security, RLS & compliance'!$N$3:$N$10,"na") -> 0 | H12: =COUNTIF('Security, RLS & compliance'!$N$3:$N$10,"unknown") -> 8 | I12: =SUMIF('Security, RLS & compliance'!$N$3:$N$10,"pass",'Security, RLS & compliance'!$T$3:$T$10)+0.5*SUMIF('Security, RLS & compliance'!$N$3:$N$10,"partial",'Security, RLS & compliance'!$T$3:$T$10) -> 0 | J12: =SUM('Security, RLS & compliance'!$T$3:$T$10)-SUMIF('Security, RLS & compliance'!$N$3:$N$10,"na",'Security, RLS & compliance'!$T$3:$T$10) -> 51
A13: Verified answers | B13: =IFERROR(ROUND(100*I13/J13,1),"n/a") -> 0 | C13: 6 | D13: =COUNTIF('Verified answers'!$N$3:$N$9,"pass") -> 0 | E13: =COUNTIF('Verified answers'!$N$3:$N$9,"partial") -> 0 | F13: =COUNTIF('Verified answers'!$N$3:$N$9,"fail") -> 0 | G13: =COUNTIF('Verified answers'!$N$3:$N$9,"na") -> 0 | H13: =COUNTIF('Verified answers'!$N$3:$N$9,"unknown") -> 7 | I13: =SUMIF('Verified answers'!$N$3:$N$9,"pass",'Verified answers'!$T$3:$T$9)+0.5*SUMIF('Verified answers'!$N$3:$N$9,"partial",'Verified answers'!$T$3:$T$9) -> 0 | J13: =SUM('Verified answers'!$T$3:$T$9)-SUMIF('Verified answers'!$N$3:$N$9,"na",'Verified answers'!$T$3:$T$9) -> 37
A14: AI instructions | B14: =IFERROR(ROUND(100*I14/J14,1),"n/a") -> 0 | C14: 6 | D14: =COUNTIF('AI instructions'!$N$3:$N$7,"pass") -> 0 | E14: =COUNTIF('AI instructions'!$N$3:$N$7,"partial") -> 0 | F14: =COUNTIF('AI instructions'!$N$3:$N$7,"fail") -> 0 | G14: =COUNTIF('AI instructions'!$N$3:$N$7,"na") -> 0 | H14: =COUNTIF('AI instructions'!$N$3:$N$7,"unknown") -> 5 | I14: =SUMIF('AI instructions'!$N$3:$N$7,"pass",'AI instructions'!$T$3:$T$7)+0.5*SUMIF('AI instructions'!$N$3:$N$7,"partial",'AI instructions'!$T$3:$T$7) -> 0 | J14: =SUM('AI instructions'!$T$3:$T$7)-SUMIF('AI instructions'!$N$3:$N$7,"na",'AI instructions'!$T$3:$T$7) -> 29
A15: Fabric data agent configuration | B15: =IFERROR(ROUND(100*I15/J15,1),"n/a") -> 0 | C15: 10 | D15: =COUNTIF('Fabric data agent configuration'!$N$3:$N$12,"pass") -> 0 | E15: =COUNTIF('Fabric data agent configuration'!$N$3:$N$12,"partial") -> 0 | F15: =COUNTIF('Fabric data agent configuration'!$N$3:$N$12,"fail") -> 0 | G15: =COUNTIF('Fabric data agent configuration'!$N$3:$N$12,"na") -> 0 | H15: =COUNTIF('Fabric data agent configuration'!$N$3:$N$12,"unknown") -> 10 | I15: =SUMIF('Fabric data agent configuration'!$N$3:$N$12,"pass",'Fabric data agent configuration'!$T$3:$T$12)+0.5*SUMIF('Fabric data agent configuration'!$N$3:$N$12,"partial",'Fabric data agent configuration'!$T$3:$T$12) -> 0 | J15: =SUM('Fabric data agent configuration'!$T$3:$T$12)-SUMIF('Fabric data agent configuration'!$N$3:$N$12,"na",'Fabric data agent configuration'!$T$3:$T$12) -> 43
A16: Performance & query efficiency | B16: =IFERROR(ROUND(100*I16/J16,1),"n/a") -> 0 | C16: 9 | D16: =COUNTIF('Performance & query efficiency'!$N$3:$N$10,"pass") -> 0 | E16: =COUNTIF('Performance & query efficiency'!$N$3:$N$10,"partial") -> 0 | F16: =COUNTIF('Performance & query efficiency'!$N$3:$N$10,"fail") -> 0 | G16: =COUNTIF('Performance & query efficiency'!$N$3:$N$10,"na") -> 0 | H16: =COUNTIF('Performance & query efficiency'!$N$3:$N$10,"unknown") -> 8 | I16: =SUMIF('Performance & query efficiency'!$N$3:$N$10,"pass",'Performance & query efficiency'!$T$3:$T$10)+0.5*SUMIF('Performance & query efficiency'!$N$3:$N$10,"partial",'Performance & query efficiency'!$T$3:$T$10) -> 0 | J16: =SUM('Performance & query efficiency'!$T$3:$T$10)-SUMIF('Performance & query efficiency'!$N$3:$N$10,"na",'Performance & query efficiency'!$T$3:$T$10) -> 55
A17: Response validity & relevance | B17: =IFERROR(ROUND(100*I17/J17,1),"n/a") -> 0 | C17: 10 | D17: =COUNTIF('Response validity & relevance'!$N$3:$N$15,"pass") -> 0 | E17: =COUNTIF('Response validity & relevance'!$N$3:$N$15,"partial") -> 0 | F17: =COUNTIF('Response validity & relevance'!$N$3:$N$15,"fail") -> 0 | G17: =COUNTIF('Response validity & relevance'!$N$3:$N$15,"na") -> 0 | H17: =COUNTIF('Response validity & relevance'!$N$3:$N$15,"unknown") -> 13 | I17: =SUMIF('Response validity & relevance'!$N$3:$N$15,"pass",'Response validity & relevance'!$T$3:$T$15)+0.5*SUMIF('Response validity & relevance'!$N$3:$N$15,"partial",'Response validity & relevance'!$T$3:$T$15) -> 0 | J17: =SUM('Response validity & relevance'!$T$3:$T$15)-SUMIF('Response validity & relevance'!$N$3:$N$15,"na",'Response validity & relevance'!$T$3:$T$15) -> 120
A18: Operations, ALM & adoption | B18: =IFERROR(ROUND(100*I18/J18,1),"n/a") -> 0 | C18: 6 | D18: =COUNTIF('Operations, ALM & adoption'!$N$3:$N$9,"pass") -> 0 | E18: =COUNTIF('Operations, ALM & adoption'!$N$3:$N$9,"partial") -> 0 | F18: =COUNTIF('Operations, ALM & adoption'!$N$3:$N$9,"fail") -> 0 | G18: =COUNTIF('Operations, ALM & adoption'!$N$3:$N$9,"na") -> 0 | H18: =COUNTIF('Operations, ALM & adoption'!$N$3:$N$9,"unknown") -> 7 | I18: =SUMIF('Operations, ALM & adoption'!$N$3:$N$9,"pass",'Operations, ALM & adoption'!$T$3:$T$9)+0.5*SUMIF('Operations, ALM & adoption'!$N$3:$N$9,"partial",'Operations, ALM & adoption'!$T$3:$T$9) -> 0 | J18: =SUM('Operations, ALM & adoption'!$T$3:$T$9)-SUMIF('Operations, ALM & adoption'!$N$3:$N$9,"na",'Operations, ALM & adoption'!$T$3:$T$9) -> 34
A20: OVERALL (weighted) | B20: =IFERROR(ROUND(SUMPRODUCT(B4:B18,C4:C18)/SUM(C4:C18),1),0) -> 0 | D20: =SUM(D4:D18) -> 0 | E20: =SUM(E4:E18) -> 0 | F20: =SUM(F4:F18) -> 0 | G20: =SUM(G4:G18) -> 0 | H20: =SUM(H4:H18) -> 138 | I20: =SUM(I4:I18) -> 0 | J20: =SUM(J4:J18) -> 836
A21: Blocker rules not met | B21: =IF(OR('Tenant & admin enablement'!N3="fail",'Tenant & admin enablement'!N3="unknown"),1,0)+IF(OR('Tenant & admin enablement'!N4="fail",'Tenant & admin enablement'!N4="unknown"),1,0)+IF(OR('Capacity, SKU, region & cost'!N3="fail",'Capacity, SKU, region & cost'!N3="unknown"),1,0)+IF(OR('Capacity, SKU, region & cost'!N4="fail",'Capacity, SKU, region & cost'!N4="unknown"),1,0)+IF(OR('AI data schema & scope reductio'!N3="fail",'AI data schema & scope reductio'!N3="unknown"),1,0)+IF(OR('Names, descriptions & linguisti'!N8="fail",'Names, descriptions & linguisti'!N8="unknown"),1,0)+IF(OR('Security, RLS & compliance'!N3="fail",'Security, RLS & compliance'!N3="unknown"),1,0)+IF(OR('Response validity & relevance'!N3="fail",'Response validity & relevance'!N3="unknown"),1,0) -> 8
A22: Maturity level | B22: =IF(B21>0,"Not Ready (GATED)",IF(B20<40,"Not Ready",IF(B20<60,"Foundational",IF(B20<75,"Operational",IF(B20<90,"Optimized","AI-Ready"))))) -> Not Ready (GATED)
A24: Gate rule | B24: Any blocker rule left at fail or unknown forces the maturity level to Not Ready, whatever the numeric score. There are 8 blocker rules in this pack.
A25: Bands | B25: Not Ready 0-39.99 | Foundational 40-59.99 | Operational 60-74.99 | Optimized 75-89.99 | AI-Ready 90-100

Sheet Tenant & admin enablement
A1: Tenant & admin enablement - 9 rules, area weight 10 | J1: Fill the yellow cells only. Result must be one of: unknown, pass, partial, fail, na
A2: Rule ID | B2: Title | C2: Severity | D2: Type | E2: Applies to | F2: Requirement | G2: Why it matters | H2: Hard limit | I2: How to check | J2: Remediation | K2: If not fixed | L2: Source | M2: Basis | N2: Result | O2: Evidence / link | P2: Owner | Q2: Due date | R2: Notes | T2: _weight
A3: TEN-001 | B3: Copilot / Azure OpenAI tenant switch is enabled for the intended audience | C3: blocker | D3: enablement | E3: copilot-powerbi, fabric-data-agent | F3: The tenant setting 'Users can use Copilot and other features powered by Azure OpenAI' must be enabled, scoped either to the whole organization or to the specific security groups that are in scope for AI. | G3: This is the master switch. Every downstream Copilot and data agent experience depends on it. | I3: (admin-portal) Fabric Admin Portal > Tenant settings > Copilot and Agent. Record state and the security groups it is scoped to. [expected: enabled] | J3: Enable the setting and scope it to the AI pilot security group rather than the entire organization, so that usage and capacity burn stay attributable during rollout. | K3: No Copilot or data agent functionality at all. | L3: Enable Fabric Copilot for Power BI; Copilot and Agent admin settings; Configure Fabric data agent tenant settings | M3: documented | N3: unknown | R3: Microsoft docs are inconsistent on the default state of this switch: the Copilot and Agent admin settings page and the Power BI enablement page describe it as enabled by default, while the data agent tenant settings page lists it as off. Do not assume - read the actual tenant state and record it as evidence. | T3: 13
A4: TEN-002 | B4: Cross-geo processing switch matches the capacity's region | C4: blocker | D4: enablement | E4: copilot-powerbi, fabric-data-agent | F4: If the Fabric capacity is outside the US regions and the EU Data Boundary, the tenant setting 'Data sent to Azure OpenAI can be processed outside your capacity's geographic region, compliance boundary, or national cloud instance' must be enabled, and that decision must be signed off by the data-residency owner. | G4: Azure OpenAI is deployed in US datacenters and the EU Data Boundary only. UK capacities route to the EU boundary; Australia, Brazil, Canada, India, Asia, Japan, Korea, South Africa, Southeast Asia and UAE route to the US. Without the switch, Copilot simply does not work in those regions. | I4: (admin-portal) Determine the capacity's region, then check the cross-geo processing tenant setting. Record both, plus the residency sign-off reference. [expected: enabled when capacity region is outside US and EU Data Boundary] | J4: Either enable cross-geo processing with documented residency approval, or relocate the capacity into a region where Azure OpenAI is served locally. | K4: Copilot requests fail in-region; users experience errors rather than degraded answers. | L4: Overview of Copilot in Fabric; Copilot and Agent admin settings | M4: documented | N4: unknown | T4: 13
A5: TEN-003 | B5: Cross-geo storage and conversation-history switches are a deliberate decision | C5: high | D5: governance | E5: fabric-data-agent, copilot-notebooks | F5: For tenants outside the EU Data Boundary and US, the settings 'Data sent to Azure OpenAI can be stored outside...' and 'Conversation history stored outside your capacity's geographic region...' must be explicitly decided - enabled with residency approval, or accepted as disabled with the loss of multi-session context understood. | G5: Conversation history is what gives agentic experiences memory across sessions; it is retained 28 days unless a user deletes it. Leaving these off outside EU/US silently degrades multi-turn quality. | H5: 28 days (hard) | I5: (admin-portal) Record both switch states and the documented decision. Both default to disabled. [expected: documented decision] | J5: Record the decision in the AI governance register. If disabled, set user expectations that each session starts cold. | K5: Agents lose cross-session context; users repeat themselves and blame the agent for forgetting. | L5: Copilot and Agent admin settings; Configure Fabric data agent tenant settings; Overview of Copilot in Fabric | M5: documented | N5: unknown | T5: 5
A6: TEN-004 | B6: 'Only show approved items in the standalone Copilot' is enabled once an approval process exists | C6: critical | D6: governance | E6: copilot-powerbi | F6: Once the organization has a working 'Approved for Copilot' review process, the tenant setting 'Only show approved items in the standalone Copilot in Power BI experience' should be enabled so standalone Copilot searches only curated content. | G6: This is the single most effective lever against the ad-hoc-scan behaviour: it stops standalone Copilot from ranging across every semantic model in the tenant and restricts it to models that have actually been prepared for AI. | I6: (admin-portal) Check the tenant setting state, and confirm at least one model has been marked Approved for Copilot. [expected: enabled] | J6: Stand up the approval review first (see WSP-004), then flip this switch. Enabling it with zero approved items makes standalone Copilot return nothing. | K6: Standalone Copilot searches unprepared models and produces confident answers from models nobody has validated. | L6: Copilot and Agent admin settings; Enable Fabric Copilot for Power BI | M6: documented | N6: unknown | T6: 8
A7: TEN-005 | B7: Standalone Copilot experience switch state is intentional | C7: high | D7: governance | E7: copilot-powerbi | F7: The setting 'Users can access a standalone, cross-item Copilot in Power BI experience' must be explicitly set on or off with a recorded rationale, not left at whatever the default happens to be. | G7: Standalone Copilot has the broadest blast radius of any Copilot surface because it is not anchored to one report. It also depends on the parent Azure OpenAI switch and is unavailable in Spain Central, Qatar, India-West and Mexico. | I7: (admin-portal) Record switch state, target groups, and the rationale. Confirm the tenant home region is not one of the unsupported regions. [expected: documented decision] | J7: Keep it off until model preparation and approval reach Optimized maturity, then enable narrowly. | K7: Broad, ungrounded question surface exposed before models are ready. | L7: Copilot and Agent admin settings; Prepare your data for AI to improve Copilot results (preview) | M7: documented | N7: unknown | T7: 5
A8: TEN-006 | B8: Fabric Copilot capacity designation is configured for cost attribution | C8: high | D8: governance | E8: copilot-powerbi, fabric-data-agent | F8: If Copilot cost needs to be isolated from analytical workloads, the setting 'Capacities can be designated as Copilot in Fabric capacities' must be enabled and a dedicated Copilot capacity assigned. | G8: Copilot consumes the same CU pool as everything else. A dedicated Copilot capacity consolidates AI billing and prevents AI spikes from throttling refreshes and report queries. | I8: (admin-portal) Check the tenant setting, then check whether a capacity is designated and which users or groups are assigned to it. [expected: designated capacity or documented decision not to] | J8: Designate a Copilot capacity and assign the AI audience to it, so AI Query operations are separately visible in the Capacity Metrics app. | K8: AI consumption is indistinguishable from BI consumption; throttling incidents cannot be attributed. | L8: Copilot and Agent admin settings; Configure Fabric data agent tenant settings; Enable Fabric Copilot for Power BI | M8: documented | N8: unknown | T8: 5
A9: TEN-007 | B9: Capacity-level Copilot delegation is reviewed, not just tenant settings | C9: high | D9: governance | E9: copilot-powerbi, fabric-data-agent | F9: Delegated tenant settings on each in-scope capacity must be reviewed, because a capacity administrator can enable Copilot at capacity level even where it is disabled at tenant level. | G9: Reviewing only the tenant page gives a false sense of control. Cross-geo delegation notably does not auto-delegate and must be set per capacity. | I9: (admin-portal) Admin Portal > Capacity settings > each capacity > Delegated tenant settings. Record any capacity that overrides the tenant position. [expected: per-capacity review record] | J9: Audit every capacity's delegated settings and reconcile overrides against the intended tenant policy. | K9: Shadow Copilot enablement on capacities the AI governance team does not know about. | L9: Enable Fabric Copilot for Power BI | M9: documented | N9: unknown | T9: 5
A10: TEN-008 | B10: Purview DLP and access-restriction policies are evaluated for AI surfaces | C10: critical | D10: governance | E10: fabric-data-agent | F10: Where the tenant is governed by Microsoft Purview, DLP policies for Fabric Data Warehouse and access-restriction policies for KQL Database, SQL Database and Data Warehouse must be reviewed against the data an agent can reach. | G10: An agent inherits the user's read access; Purview policies are the layer that prevents an otherwise-authorized query from surfacing regulated content in a chat response. | I10: (manual) List agent data sources, then confirm each has been assessed against active Purview DLP and access-restriction policies. [expected: assessment record per data source] | J10: Run a Purview policy review as part of agent intake; block sources that carry regulated data without a policy. | K10: Regulated data surfaced conversationally with no DLP interception. | L10: Fabric data agent creation | M10: documented | N10: unknown | T10: 8
A11: TEN-009 | B11: Tenant setting changes are allowed an hour to propagate before troubleshooting | C11: low | D11: governance | E11: copilot-powerbi, fabric-data-agent | F11: The runbook must state that Copilot and data agent tenant settings can take up to one hour to take effect, and that troubleshooting should not begin before that window elapses. | G11: Most 'Copilot is broken after we enabled it' escalations are impatience. Codifying the wait prevents wasted support cycles and premature setting churn. | H11: 1 hours (soft) | I11: (manual) Confirm the enablement runbook documents the propagation delay. [expected: documented in runbook] | J11: Add the one-hour propagation note to the enablement runbook and the support script. | K11: Settings toggled repeatedly during the propagation window, confusing the audit trail. | L11: Configure Fabric data agent tenant settings | M11: documented | N11: unknown | T11: 1

Sheet Capacity, SKU, region & cost
A1: Capacity, SKU, region & cost - 6 rules, area weight 10 | J1: Fill the yellow cells only. Result must be one of: unknown, pass, partial, fail, na
A2: Rule ID | B2: Title | C2: Severity | D2: Type | E2: Applies to | F2: Requirement | G2: Why it matters | H2: Hard limit | I2: How to check | J2: Remediation | K2: If not fixed | L2: Source | M2: Basis | N2: Result | O2: Evidence / link | P2: Owner | Q2: Due date | R2: Notes | T2: _weight
A3: CAP-001 | B3: Capacity meets the minimum paid SKU | C3: blocker | D3: limit | E3: copilot-powerbi, fabric-data-agent | F3: Every workspace hosting a Copilot-enabled model or a data agent must be on a paid Fabric capacity of F2 or higher, or Power BI Premium P1 or higher with Fabric enabled. | G3: Trial SKUs are not supported for Azure OpenAI access. This is a hard gate, not a performance recommendation. | H3: F2 / P1 sku (hard) | I3: (api) Enumerate in-scope workspaces and their assigned capacity SKU. Flag any on trial, PPU-only, or shared capacity. [gte F2] | J3: Move the workspace to a qualifying paid capacity, or assign users to a Fabric Copilot capacity. | K3: Copilot and data agent features are unavailable regardless of tenant settings. | L3: Fabric data agent creation; Overview of Copilot in Fabric; Use Copilot with semantic models in Power BI | M3: documented | N3: unknown | T3: 13
A4: CAP-002 | B4: Capacity region is supported and consistent across agent and sources | C4: blocker | D4: limit | E4: fabric-data-agent | F4: The data agent's workspace capacity and every data source workspace capacity must be in the same region, and that region must be one where Fabric AI workloads are available. | G4: Cross-region source binding fails outright - a Lakehouse on North Europe capacity will not serve an agent whose capacity is in France Central. Sovereign clouds are not supported at all. | I4: (api) For each agent, list the region of its own capacity and of every bound data source's capacity. All must match. [expected: identical region across agent and all sources] | J4: Relocate either the agent workspace or the source workspaces so all sit on same-region capacity. | K4: Agent creation or query execution fails against the mismatched source. | L4: Fabric data agent creation; Overview of Copilot in Fabric | M4: documented | N4: unknown | T4: 13
A5: CAP-003 | B5: AI Query consumption is monitored in the Capacity Metrics app | C5: critical | D5: performance | E5: fabric-data-agent, copilot-powerbi | F5: AI Query operations and the LlmPlugin item kind must be actively monitored in the Fabric Capacity Metrics app, with a named owner and a review cadence. | G5: Data agent requests bill at 100 CU seconds per 1,000 input tokens, 10 CU seconds per 1,000 cached input tokens, and 400 CU seconds per 1,000 output tokens - and the generated SQL/DAX/KQL is billed separately to its own engine on top. Without monitoring, a verbose instruction set silently multiplies cost on every single question. | H5: inputPer1kTokens=100; cachedInputPer1kTokens=10; outputPer1kTokens=400 CU seconds (hard) | I5: (metrics) Capacity Metrics app, filter to AI Query operations and the LlmPlugin item kind. Confirm a monitoring owner and cadence exist. [expected: monitored with named owner] | J5: Add AI Query to the capacity review pack; alert on week-over-week growth and on the ratio of output to input tokens. | K5: Unbounded AI spend and eventual capacity-wide throttling that takes refreshes down with it. | L5: Data agent consumption | M5: documented | N5: unknown | T5: 8
A6: CAP-004 | B6: Throttling risk from AI workloads is assessed against the SKU | C6: high | D6: performance | E6: fabric-data-agent, copilot-powerbi | F6: Expected peak AI request volume must be modelled against the capacity's daily CU budget, and the result recorded, before broad rollout. | G6: Data agent operations run as background jobs which smooth peaks, but once capacity is exhausted all operations shut down - not just AI. An F64 carrying 1,536 CU hours per day supports on the order of 13,800 requests per day before exhaustion; that number falls fast as instructions and conversation history grow. | I6: (manual) Record the SKU, its daily CU hours, the modelled average tokens per request, and the derived request ceiling. Compare against forecast adoption. [expected: documented headroom model] | J6: Model it explicitly, then either size the capacity for the forecast or cap the audience until instruction and schema trimming brings per-request tokens down. | K6: AI adoption success takes down unrelated Fabric workloads on the same capacity. | L6: Data agent consumption | M6: documented | N6: unknown | T6: 5
A7: CAP-005 | B7: Private Link and closed-network constraints are checked | C7: critical | D7: limit | E7: copilot-powerbi, fabric-data-agent | F7: Confirm that in-scope capacities do not depend on Private Link or closed-network configurations that are unsupported for Copilot. | G7: Copilot is not supported behind Private Link or closed networks. Discovering this after a rollout announcement is expensive. | I7: (admin-portal) Check tenant and workspace networking configuration for Private Link / closed-network enforcement. [expected: not enforced for AI-enabled workspaces] | J7: Carve the AI-enabled workspaces out of the Private Link enforcement scope, or accept that Copilot is unavailable there. | K7: Copilot silently unavailable despite every switch appearing correct. | L7: Enable Fabric Copilot for Power BI | M7: documented | N7: unknown | T7: 8
A8: CAP-006 | B8: Workspace outbound access protection boundaries are understood for agents | C8: medium | D8: governance | E8: fabric-data-agent | F8: Where workspace outbound access protection is in force, the permitted external endpoints must be documented and confirmed sufficient for the agent's data sources. | G8: Agents operate inside the workspace outbound access protection boundary; an administrator's endpoint allowlist directly determines what the agent can reach. | I8: (manual) Record outbound access protection state and the allowlisted endpoints for each agent workspace. [expected: documented] | J8: Reconcile the endpoint allowlist with the agent's bound sources before go-live. | K8: Intermittent, hard-to-diagnose source failures. | L8: Fabric data agent creation | M8: documented | N8: unknown | T8: 3

Sheet Workspace & item governance
A1: Workspace & item governance - 7 rules, area weight 6 | J1: Fill the yellow cells only. Result must be one of: unknown, pass, partial, fail, na
A2: Rule ID | B2: Title | C2: Severity | D2: Type | E2: Applies to | F2: Requirement | G2: Why it matters | H2: Hard limit | I2: How to check | J2: Remediation | K2: If not fixed | L2: Source | M2: Basis | N2: Result | O2: Evidence / link | P2: Owner | Q2: Due date | R2: Notes | T2: _weight
A3: WSP-001 | B3: AI-enabled workspaces are an explicit, enumerated set | C3: critical | D3: governance | E3: copilot-powerbi, fabric-data-agent | F3: There must be a maintained register of which workspaces are in scope for Copilot and data agents, rather than AI being implicitly available wherever capacity happens to be assigned. | G3: Scope control is the foundation of every other rule in this pack. You cannot tune what you have not bounded. | I3: (manual) Confirm a register exists, is current within the last quarter, and names an owner per workspace. [expected: current register] | J3: Publish the register and review it at each capacity review. | K3: AI surface expands invisibly; assessment results go stale immediately. | L3: Established semantic modeling / Copilot tuning practice (not a single Microsoft doc) | M3: inferred | N3: unknown | T3: 8
A4: WSP-002 | B4: Copilot cannot be enabled per workload - the audience decision is all-or-nothing | C4: high | D4: governance | E4: copilot-powerbi, fabric-data-agent | F4: The rollout plan must account for the fact that enabling Copilot in a capacity for a user or security group grants that group all Copilot workloads and experiences; it cannot be enabled for one experience only. | G4: Teams frequently plan a 'Copilot for Power BI only' pilot that is not technically achievable. The control point is the audience, not the workload. | I4: (manual) Confirm the rollout plan controls exposure by security group and capacity assignment, not by workload selection. [expected: audience-based scoping] | J4: Rewrite the rollout plan around security groups and dedicated capacities. | K4: Users reach Copilot experiences over unprepared workloads that were never in the pilot scope. | L4: Use Copilot with semantic models in Power BI | M4: documented | N4: unknown | T4: 5
A5: WSP-003 | B5: Staging, development and sandbox workspaces are excluded from AI capacity | C5: high | D5: governance | E5: copilot-powerbi | F5: Development, staging and personal sandbox workspaces must not sit on capacity where Copilot is enabled for business users. | G5: Half-built models with placeholder measures and unhidden technical columns are exactly the content that teaches users not to trust Copilot. | I5: (api) Cross-reference the workspace register against capacity assignment; flag any dev/test workspace on a Copilot-enabled capacity accessible to business users. [expected: no dev/test workspaces exposed] | J5: Move non-production workspaces to a separate capacity or restrict the Copilot security group to production workspace members. | K5: Users get answers from unfinished models and lose confidence permanently. | L5: Established semantic modeling / Copilot tuning practice (not a single Microsoft doc); Best practices for configuring your data agent | M5: inferred | N5: unknown | T5: 5
A6: WSP-004 | B6: 'Approved for Copilot' is applied through a real review, not by default | C6: critical | D6: governance | E6: copilot-powerbi | F6: Every semantic model marked 'Approved for Copilot' must have passed a documented review covering schema scoping, descriptions, verified answers and a golden-question test pass. | G6: Approval is the trust signal shown to users; unapproved models display a warning advising users to inspect results and contact the owner. Rubber-stamping approval destroys the signal's value. | I6: (manual) For each approved model, confirm a review record exists with a date, reviewer, and golden-question pass rate. [expected: review record per approved model] | J6: Define the approval checklist from this rule pack and gate the flag behind it. | K6: The approval badge becomes noise and users cannot tell prepared models from unprepared ones. | L6: Copilot in Power BI tutorial: prepare a semantic model for AI; Copilot and Agent admin settings | M6: documented | N6: unknown | T6: 8
A7: WSP-005 | B7: Reports, dashboards and apps cannot be approved - only semantic models | C7: low | D7: limit | E7: copilot-powerbi | F7: Governance documentation must state that there is currently no way to mark a report, dashboard or app as approved for Copilot; only semantic models carry the flag. | G7: Teams design approval workflows around reports and then find the flag does not exist, leaving the process half-implemented. | I7: (manual) Confirm the governance doc reflects the model-only scope of approval. [expected: documented] | J7: Anchor the approval process on semantic models and treat report quality as a separate control. | K7: Approval process design churn. | L7: Prepare your data for AI to improve Copilot results (preview) | M7: documented | N7: unknown | T7: 1
A8: WSP-006 | B8: Semantic model description is populated for discovery | C8: high | D8: metadata | E8: copilot-powerbi | F8: Each in-scope semantic model must have a populated description in model settings that names the subject areas, key entities and the questions it is meant to answer. | G8: Descriptions feed the Search grounding path, which is how standalone Copilot decides which model to use for a question. A blank description makes the model effectively invisible or, worse, picked at random. | I8: (api) Read the model description for every in-scope model; flag empty, default, or single-word values. [expected: non-empty, keyword-rich description] | J8: Write a description covering tables, measures, relationships and intended audience, using distinct keywords rather than generic phrasing. | K8: Standalone Copilot routes questions to the wrong model. | L8: Copilot in Power BI tutorial: prepare a semantic model for AI; Frequently asked questions about preparing data for AI | M8: documented | N8: unknown | T8: 5
A9: WSP-007 | B9: Report descriptions are populated where reports are part of the AI surface | C9: medium | D9: metadata | E9: copilot-powerbi | F9: Reports exposed to Copilot should carry a description in File > Settings that provides natural-language context for data discovery. | G9: Report descriptions contribute to discovery and to the report summary experience. | I9: (manual) Sample in-scope reports and check for a populated description. [expected: non-empty description] | J9: Add a one-to-two sentence description naming the analysis and its dimensions. | K9: Weaker discovery and less useful report summaries. | L9: Copilot in Power BI tutorial: prepare a semantic model for AI | M9: documented | N9: unknown | T9: 3

Sheet AI data schema & scope reductio
A1: AI data schema & scope reduction - 21 rules, area weight 14 | J1: Fill the yellow cells only. Result must be one of: unknown, pass, partial, fail, na
A2: Rule ID | B2: Title | C2: Severity | D2: Type | E2: Applies to | F2: Requirement | G2: Why it matters | H2: Hard limit | I2: How to check | J2: Remediation | K2: If not fixed | L2: Source | M2: Basis | N2: Result | O2: Evidence / link | P2: Owner | Q2: Due date | R2: Notes | T2: _weight
A3: SCH-001 | B3: An AI data schema is explicitly defined for every in-scope semantic model | C3: blocker | D3: config | E3: copilot-powerbi, fabric-data-agent | F3: Every semantic model exposed to Copilot or bound to a data agent must have an AI data schema defined through Prep data for AI, rather than defaulting to the full model surface. | G3: This is the primary control against the ad-hoc-SQL-server behaviour. The DAX generation tool uses only the AI data schema. If you never define one, the generator reasons over everything you own. | I3: (tmdl) Inspect the model's LSDL / AI data schema definition. Confirm a curated selection exists and is narrower than the full object list. [expected: defined and narrower than full model] | J3: Open Prep data for AI > Simplify the data schema and deselect every field not required by the intended question set. | K3: The generator considers every table, column and measure on every question - maximum latency, maximum token cost, maximum ambiguity. | L3: Copilot in Power BI tutorial: prepare a semantic model for AI; Semantic model best practices for data agent; Prepare your data for AI to improve Copilot results (preview) | M3: documented | N3: unknown | T3: 13
A4: SCH-002 | B4: Model entity count stays within the 1,000-entity indexing ceiling | C4: critical | D4: limit | E4: copilot-powerbi, fabric-data-agent | F4: The combined count of tables and columns in the model should stay at or below 1,000 entities, or the AI data schema must reduce the exposed surface to below that ceiling. | G4: Power BI indexes a maximum of 1,000 model entities (tables and columns combined) for instance-value search. Beyond that, columns go unindexed and value-based filtering silently degrades. | H4: 1000 entities (tables + columns) (hard) | I4: (dax) Count tables plus columns via INFO.TABLES()/INFO.COLUMNS() or a VPAX extract. Compare against 1000. [lte 1000 entities] | J4: Trim the model, or narrow the AI data schema so the AI-visible entity count is well under the ceiling. Aim materially below 1,000, not at it. | K4: Columns are skipped during indexing; Copilot cannot resolve filter values it should be able to find. | L4: Frequently asked questions about preparing data for AI | M4: documented | N4: unknown | T4: 8
A5: SCH-003 | B5: Instance-value indexing stays within the 5 million value ceiling | C5: critical | D5: limit | E5: copilot-powerbi | F5: The total indexed instance values across the model must stay under 5 million, and high-cardinality columns must be excluded from the AI data schema where they are not needed for filtering. | G5: Indexing stops at 5 million instance values. When the next column would push the total over, Power BI skips that column entirely - and it may be a column that matters. A single high-cardinality key can consume the budget and starve every column after it. | H5: 5000000 instance values (hard) | I5: (dax) Estimate distinct-value counts per AI-visible column (APPROXIMATEDISTINCTCOUNT or COLUMNSTATISTICS) and sum. Compare against 5,000,000. [lte 5000000 instance values] | J5: Deselect surrogate keys, GUIDs, free-text notes and transaction identifiers from the AI data schema. Keep the columns users actually name in questions. | K5: Arbitrary columns silently unindexed; value filters fail unpredictably and look like model bugs. | L5: Frequently asked questions about preparing data for AI | M5: documented | N5: unknown | T5: 8
A6: SCH-004 | B6: Filterable text values are under 100 characters | C6: high | D6: limit | E6: copilot-powerbi | F6: Columns intended for value-based filtering by Copilot must contain values shorter than 100 characters. | G6: Text values of 100 characters or more are not indexed. Long descriptive strings will never be matched by a user's natural-language filter no matter how the question is phrased. | H6: 100 characters (hard) | I6: (dax) For each AI-visible text column, compute MAX(LEN(column)). Flag any column used for filtering whose values reach 100 characters. [lt 100 characters] | J6: Split long text into a short filterable code or category column plus a long descriptive column, and expose only the short one to the AI data schema. | K6: Users filter on a value that visibly exists in the report and Copilot insists it cannot find it. | L6: Frequently asked questions about preparing data for AI | M6: documented | N6: unknown | T6: 5
A7: SCH-005 | B7: Copilot Diagnostics shows no AgentSchemaReduced warning | C7: critical | D7: validation | E7: copilot-powerbi | F7: Copilot Diagnostics must not report 'AgentSchemaReduced' for in-scope models under representative questions. | G7: AgentSchemaReduced means the schema was too large for Copilot to render and Copilot automatically cut it down - by its own choice, not yours. Whatever it dropped is invisible to the generator and you did not decide what went. | I7: (manual) Run the golden question set and inspect Copilot Diagnostics warnings for AgentSchemaReduced. [expected: warning absent] | J7: Reduce the AI data schema yourself until the warning clears, so schema reduction is a deliberate curation decision rather than an automatic truncation. | K7: Silent, uncontrolled loss of schema; answers omit data that exists and nobody can explain why. | L7: Frequently asked questions about preparing data for AI | M7: documented | N7: unknown | T7: 8
A8: SCH-006 | B8: Surrogate keys and relationship identifiers are removed from the AI schema | C8: high | D8: modeling | E8: copilot-powerbi, fabric-data-agent | F8: Unique identifier columns used only to define relationships must be deselected from the AI data schema. | G8: Documented explicitly as a field type to deselect. Keys carry no business meaning, add cardinality against the indexing budget, and invite the generator to join or group on them. | I8: (tmdl) List AI-visible columns whose names match key patterns (ID, Key, SK, GUID, Code suffixes) and confirm exclusion unless deliberately kept. [expected: excluded] | J8: Deselect them in Simplify the data schema. Relationships still work; the generator just stops seeing the keys. | K8: Grouping by meaningless identifiers, wasted index budget, and joins the generator invents rather than follows. | L8: Copilot in Power BI tutorial: prepare a semantic model for AI; Best practices for configuring your data agent | M8: documented | N8: unknown | T8: 5
A9: SCH-007 | B9: Sort-order and helper columns are removed from the AI schema | C9: high | D9: modeling | E9: copilot-powerbi | F9: Sort-by columns such as Month (Sort Order) or Day (Sort Order), and other presentation helper columns, must be deselected from the AI data schema. | G9: Called out explicitly as fields to deselect. They duplicate a real attribute in numeric form, so the generator has two plausible columns for one concept and picks wrong roughly half the time. | I9: (tmdl) Identify columns used as Sort By Column targets and confirm they are excluded from the AI schema. [expected: excluded] | J9: Deselect all sort-order columns. Sorting behaviour in visuals is unaffected. | K9: Answers grouped by 1..12 instead of month names; user trust erodes on cosmetic-looking errors. | L9: Copilot in Power BI tutorial: prepare a semantic model for AI | M9: documented | N9: unknown | T9: 5
A10: SCH-008 | B10: Archived, staging and audit tables are excluded | C10: high | D10: modeling | E10: copilot-powerbi, fabric-data-agent | F10: Archived, staging, audit and unrelated tables must be excluded from both the AI data schema and any data agent object selection. | G10: Explicit guidance for data agent configuration: select only the tables, columns, views and functions needed for the intended questions. Staging tables are the classic source of near-duplicate results. | I10: (manual) Review the AI-visible table list against the intended question set; flag any table that no in-scope question needs. [expected: excluded] | J10: Remove them from selection. If they must stay in the model for lineage, hide them and exclude them from the AI schema. | K10: The generator queries a staging copy and returns numbers that do not tie to any published report. | L10: Best practices for configuring your data agent | M10: documented | N10: unknown | T10: 5
A11: SCH-009 | B11: AI data schema is scoped to a declared question set | C11: critical | D11: governance | E11: copilot-powerbi, fabric-data-agent | F11: Each AI data schema must be traceable to a written statement of the question scope the model is meant to serve, and every included object must be justified by at least one question in that scope. | G11: 'Select only relevant objects based on the data agent's question scope to reduce ambiguity and latency.' Without a declared scope, inclusion decisions are arbitrary and the schema only ever grows. | I11: (manual) Confirm a question-scope document exists per model/agent and that schema inclusions map to it. [expected: documented question scope] | J11: Write the scope statement first, derive the schema from it, and reject additions that no scoped question requires. | K11: Schema sprawl returns within two release cycles and undoes every other tuning effort. | L11: Semantic model best practices for data agent; Best practices for configuring your data agent | M11: documented | N11: unknown | T11: 8
A12: SCH-010 | B12: Data agent object selection matches the model's AI data schema | C12: critical | D12: config | E12: fabric-data-agent | F12: For a semantic model bound to a data agent, the tables selected in the data agent must be the same tables defined in the model's Prep for AI AI data schema. | G12: Stated as a direct consistency rule. Divergence means the agent exposes objects the DAX generator was never configured to reason about. | I12: (manual) Diff the agent's selected object list against the model's AI data schema. The sets must match. [expected: identical object sets] | J12: Reconcile the two selections and add a check to the release process so they cannot drift. | K12: Objects visible to the agent but absent from the generation schema produce failed or nonsensical DAX. | L12: Semantic model best practices for data agent | M12: documented | N12: unknown | T12: 8
A13: SCH-011 | B13: Dependent objects of selected measures are included in the schema | C13: critical | D13: config | E13: copilot-powerbi, fabric-data-agent | F13: When a measure is included in the AI data schema, every object it depends on must also be included. | G13: Explicit dependency rule; Semantic Link Labs' get_measure_dependencies is the recommended way to enumerate them. A measure whose dependencies were trimmed away fails at query time. | I13: (api) Run get_measure_dependencies (Semantic Link Labs) across AI-visible measures and confirm every dependency is also AI-visible. [expected: all dependencies present] | J13: Add the missing dependencies, or drop the measure from the schema if its dependencies must stay hidden. | K13: Generated DAX references objects the generator believes exist and the query errors. | L13: Semantic model best practices for data agent | M13: documented | N13: unknown | T13: 8
A14: SCH-012 | B14: Hidden fields are not silently relied upon | C14: critical | D14: config | E14: copilot-powerbi, fabric-data-agent | F14: Any field that Copilot must be able to use has to be visible; hidden measures and columns are excluded from grounding and must not appear in verified answers. | G14: Hidden fields are excluded from grounding data, and verified answers referencing hidden columns simply do not work. Teams routinely hide a column for report tidiness and then wonder why Copilot cannot answer about it. | I14: (dax) List objects referenced by verified answers and by the question scope, and confirm none are hidden. [expected: no hidden objects in AI scope] | J14: Unhide the fields Copilot needs, or rewrite the verified answer against visible equivalents. | K14: Verified answers fail silently and Copilot claims data it can see in reports does not exist. | L14: Use Copilot with semantic models in Power BI; Semantic model best practices for data agent | M14: documented | N14: unknown | T14: 8
A15: SCH-013 | B15: Private tables are understood to be entirely invisible to Copilot | C15: high | D15: config | E15: copilot-powerbi | F15: Tables marked private must be documented as fully excluded from all Copilot grounding, and no AI capability may depend on them. | G15: Copilot ignores private tables entirely across both the data-question and DAX query view paths. This is a useful deliberate exclusion mechanism, but a trap when unintentional. | I15: (tmdl) List tables marked private and confirm no in-scope question depends on them. [expected: documented and no dependency] | J15: Use the private flag deliberately to fence off sensitive or technical tables; unmark any table Copilot legitimately needs. | K15: Unexplainable gaps in Copilot's knowledge of the model. | L15: Use Copilot with semantic models in Power BI | M15: documented | N15: unknown | T15: 5
A16: SCH-014 | B16: Duplicate field names across tables are eliminated or disambiguated | C16: high | D16: modeling | E16: copilot-powerbi, fabric-data-agent | F16: The AI-visible schema must not contain identically named fields in multiple tables unless each carries a description that distinguishes it. | G16: Called out directly: 'Name' in a Customer table versus a Store table forces the generator to guess. Ambiguity at schema level cannot be recovered by a better prompt. | I16: (dax) Group AI-visible column and measure names; flag any name appearing in more than one table. [equals 0] | J16: Rename to Customer Name / Store Name, or add distinguishing descriptions to each. | K16: Roughly random field selection on any question naming the ambiguous term. | L16: Copilot in Power BI tutorial: prepare a semantic model for AI; Semantic model best practices for data agent | M16: documented | N16: unknown | T16: 5
A17: SCH-015 | B17: Instance-value reindexing cadence is understood and accounted for | C17: medium | D17: performance | E17: copilot-powerbi | F17: The team must document the reindexing behaviour that applies to each model type and set user expectations accordingly. | G17: Import models reindex on manual or scheduled refresh, but only when Copilot or Q&A has been used in the last 14 days. DirectQuery and Direct Lake reindex when the index is older than 24 hours under the same 14-day activity condition, with COLUMNSTATISTICS cached for 7 days. A model nobody has asked a question of for two weeks stops being reindexed. | H17: activityWindowDays=14; directQueryReindexHours=24; columnStatisticsCacheDays=7; firstIndexMinutes=15 mixed (hard) | I17: (manual) Confirm the operations runbook records the reindexing rules per model type and the 14-day activity dependency. [expected: documented] | J17: Document it, and for low-traffic but important models schedule a periodic synthetic question to keep the model within the activity window. | K17: Stale instance values produce filter misses that look like data errors. | L17: Frequently asked questions about preparing data for AI | M17: documented | N17: unknown | T17: 3
A18: SCH-016 | B18: DirectQuery indexing constraints are accepted or mitigated | C18: medium | D18: limit | E18: copilot-powerbi | F18: For DirectQuery models, confirm the source supports APPROXIMATEDISTINCTCOUNT and accept that indexing occurs at most once per 24 hours unless the model is republished. | G18: Only columns from sources supporting APPROXIMATEDISTINCTCOUNT are indexed at all. A failed underlying refresh leaves a stale index until the next successful one. | I18: (manual) For each DirectQuery model, record source support for APPROXIMATEDISTINCTCOUNT and the observed index age. [expected: documented] | J18: Where the source does not support it, consider Import or Direct Lake for the AI-facing model. | K18: Value filtering effectively unavailable on DirectQuery models against unsupported sources. | L18: Frequently asked questions about preparing data for AI | M18: documented | N18: unknown | T18: 3
A19: SCH-017 | B19: Prep for AI changes are given time to propagate before re-testing | C19: low | D19: operations | E19: copilot-powerbi | F19: Test cycles must allow up to 24 hours for Prep for AI changes to affect Copilot results, typically within an hour, with the longer tail on models that have many attached reports. | G19: Re-testing five minutes after a change and concluding the change did nothing leads to thrashing the configuration. | H19: 24 hours (soft) | I19: (manual) Confirm the test procedure documents the propagation window. [expected: documented] | J19: Build the wait into the evaluation cadence; batch configuration changes rather than tuning one setting at a time. | K19: Configuration churn and false conclusions about which settings help. | L19: Prepare your data for AI to improve Copilot results (preview) | M19: documented | N19: unknown | T19: 1
A20: SCH-018 | B20: Prep for AI edits deployed via Git or pipelines are followed by a refresh | C20: high | D20: operations | E20: copilot-powerbi | F20: After deploying LSDL or Prep for AI changes through Git integration or deployment pipelines, the model must be refreshed in the Power BI service to sync the changes. | G20: Explicit requirement. Import models must be refreshed; DirectQuery and Direct Lake models must be refreshed but only once a day. Skipping this leaves production running the previous AI configuration while source control says otherwise. | I20: (manual) Confirm the deployment pipeline includes a post-deployment refresh step for AI-configured models. [expected: refresh step present] | J20: Add the refresh to the release pipeline and verify the AI configuration post-deployment rather than assuming it landed. | K20: Deployed AI configuration silently inactive in production. | L20: Prepare your data for AI to improve Copilot results (preview) | M20: documented | N20: unknown | T20: 5
A21: SCH-019 | B21: Connection type is supported for Desktop-based Prep for AI authoring | C21: medium | D21: limit | E21: copilot-powerbi | F21: Where Prep for AI is authored in Power BI Desktop, the model must use Import, DirectQuery or local Composite mode. | G21: Power BI Desktop supports only those connection types for Prep data for AI. All model types can use the features in the Power BI service, so the constraint is on where you author, not where you consume. | I21: (manual) Record the connection type of each model and where its AI configuration is authored. | J21: Author Prep for AI in the service for model types Desktop does not support. | K21: Prep for AI unavailable in Desktop and the team assumes the feature is broken. | L21: Prepare your data for AI to improve Copilot results (preview) | M21: documented | N21: unknown | T21: 3
